<mujoco model="two_arms">
  <compiler meshdir="meshes" angle="degree"/>
  <option timestep="0.002" gravity="0 0 -9.81"/>

  <asset>
    <mesh name="Shoulder" file="Shoulder.STL" scale="0.001 0.001 0.001"/>
    <mesh name="Bicep"    file="Bicep.STL"    scale="0.001 0.001 0.001"/>
    <mesh name="Elbow"    file="Elbow.STL"    scale="0.001 0.001 0.001"/>
    <mesh name="Forearm"  file="Forearm.STL"  scale="0.001 0.001 0.001" refpos="0 0 0.0"/>
    <mesh name="Palm"     file="Palm.STL"     scale="0.001 0.001 0.001"/>
    <mesh name="Palm2"    file="Palm2.STL"    scale="0.001 0.001 0.001"/>
    <mesh name="Pointer1" file="Pointer1.STL" scale="0.001 0.001 0.001"/>
    <mesh name="Pointer2" file="Pointer2.STL" scale="0.001 0.001 0.001"/>
    <mesh name="Pointer3" file="Pointer3.STL" scale="0.001 0.001 0.001"/>
    <mesh name="Thumb1"   file="Thumb1.STL"   scale="0.001 0.001 0.001"/>
    <mesh name="Thumb2"   file="Thumb2.STL"   scale="0.001 0.001 0.001"/>
  </asset>

  <worldbody>
    <!-- LEFT ARM -->
    <body name="L_base" pos="0 0.22 0">
      <geom type="mesh" mesh="Shoulder" density="1000"/>

      <body name="L_link1" pos="-0.25 -0.1 -0.07">
        <joint name="L_joint1" type="hinge" pos="0 0 0" axis="0 0 1" range="-35 40" damping="1"/>
        <geom name="L_joint1_marker" type="sphere" pos="0 0 0" size="0.015" contype="0" conaffinity="0"/>
        <geom name="L_link1_vis" type="mesh" mesh="Bicep"
              contype="0" conaffinity="0"
              pos="0.24 0.145 0.07"
              euler="0 0 10.305"/>

        <body name="L_link2" pos="0.23 0.0344 -0.038" gravcomp="1">
          <joint name="L_joint2" type="hinge" pos="0 0 0" axis="0 1 0" range="-90 20" damping="1"/>
          <geom name="L_joint2_marker" type="sphere" pos="0 0 0" size="0.015" rgba="0 0 0 0" contype="0" conaffinity="0"/>
          <geom name="L_link2_vis" type="mesh" mesh="Elbow"
                contype="0" conaffinity="0"
                pos="0.03 0.11 0.11"
                euler="0 0 0"/>

          <body name="L_link3" pos="0 0 0" euler="0 0 11" gravcomp="1">
            <joint name="L_joint3" type="hinge" pos="0 0 0" axis="1 0 0" range="-90 180" damping="1" armature="0.01"/>
            <geom name="L_joint3_marker" type="sphere" pos="0 0 0" size="0.012" contype="0" conaffinity="0"/>
            <geom type="mesh" mesh="Forearm" contype="0" conaffinity="0"
                  pos="0.03 0.1 0.11"
                  euler="0 0 0"/>

            <body name="L_link4" pos="0.28 0 0" gravcomp="1">
              <geom name="L_joint4_marker" type="sphere" pos="0 0 0" size="0.015" rgba="0 0 0 0" contype="0" conaffinity="0"/>
              <geom name="L_link4_vis" type="mesh" mesh="Palm"
                    contype="0" conaffinity="0"
                    pos="-0.242 0.214 0.049"
                    euler="0 0 0"/>

              <body name="L_link5" pos="0 0.007 -0.005" gravcomp="1">
                <joint name="L_joint5" type="hinge" pos="0 0 0" axis="1 0 0" range="-35 40" damping="1"/>
                <geom name="L_joint5_marker" type="capsule" pos="0 0.025 0" size="0.004 0.02" euler="90 0 0" rgba="0 1 0 1" contype="0" conaffinity="0"/>
                <geom type="mesh" mesh="Palm2" contype="0" conaffinity="0" pos="-0.242 0.207 0.055" euler="0 0 0"/>

                <body name="L_flink9" pos="0 0.035 0" gravcomp="1" euler="90 0 0">
                  <joint name="L_fjoint9" type="hinge" pos="0 0 0" axis="0 1 0" range="0 40" limited="true" damping="1"/>
                  <geom name="L_fjoint9_marker" type="capsule" pos="0.01 0.0 -0.02" size="0.004 0.01" euler="0 0 0" rgba="0 1 0 1" contype="0" conaffinity="0"/>
                  <geom type="mesh" mesh="Thumb1" contype="0" conaffinity="0" pos="-0.255 0.12 -0.059" euler="-90 0 0"/>

                  <body name="L_flink10" pos="0.027 0 0" gravcomp="1">
                    <joint name="L_fjoint10" type="hinge" pos="0 0 0" axis="0 1 0" range="0 20" limited="true" damping="1"/>
                    <geom name="L_fjoint10_marker" type="capsule" pos="0.01 0 0" size="0.004 0.01" euler="0 0 0" rgba="0 0 0 0" contype="0" conaffinity="0"/>
                    <geom type="mesh" mesh="Thumb2" contype="0" conaffinity="0" pos="-0.283 0.12 -0.058" euler="-90 0 0"/>
                  </body>
                </body>
              </body>

              <body name="L_link6" pos="0.075 0.03 -0.007" gravcomp="1" euler="0 0 0">
                <joint name="L_joint6" type="hinge" pos="0 0 0" axis="0 1 0" range="0 20" limited="true" damping="1"/>
                <geom name="L_joint6_marker" type="capsule" pos="0.01 0 0" size="0.004 0.01" euler="90 90 0" rgba="0 1 0 1" contype="0" conaffinity="0"/>
                <geom type="mesh" mesh="Pointer1" contype="0" conaffinity="0" pos="-0.319 0.182 0.055" euler="0 0 0"/>

                <body name="L_link7" pos="0.027 0 0" gravcomp="1">
                  <joint name="L_joint7" type="hinge" pos="0 0 0" axis="0 1 0" range="0 20" limited="true" damping="1"/>
                  <geom name="L_joint7_marker" type="capsule" pos="0.01 0 0" size="0.004 0.01" euler="90 90 0" rgba="0 0 0 0" contype="0" conaffinity="0"/>
                  <geom type="mesh" mesh="Pointer2" contype="0" conaffinity="0" pos="-0.347 0.1815 0.055" euler="0 0 0"/>

                  <body name="L_link8" pos="0.027 0 0" gravcomp="1">
                    <joint name="L_joint8" type="hinge" pos="0 0 0" axis="0 1 0" range="0 20" limited="true" damping="1"/>
                    <geom name="L_joint8_marker" type="capsule" pos="0.01 0 0" size="0.004 0.01" euler="90 90 0" rgba="0 0 0 0" contype="0" conaffinity="0"/>
                    <geom type="mesh" mesh="Pointer3" contype="0" conaffinity="0" pos="-0.383 0.0685 0.117" euler="0 0 0"/>
                  </body>
                </body>
              </body>

              <body name="L_link9" pos="0.075 0.009 -0.006" gravcomp="1" euler="0 0 -10">
                <joint name="L_joint9" type="hinge" pos="0 0 0" axis="0 1 0" range="0 20" limited="true" damping="1"/>
                <geom name="L_joint9_marker" type="capsule" pos="0.01 0 0" size="0.004 0.01" euler="90 90 0" rgba="0 0 0 0" contype="0" conaffinity="0"/>
                <geom type="mesh" mesh="Pointer1" contype="0" conaffinity="0" pos="-0.319 0.182 0.055" euler="0 0 0"/>

                <body name="L_link10" pos="0.027 0 0" gravcomp="1">
                  <joint name="L_joint10" type="hinge" pos="0 0 0" axis="0 1 0" range="0 20" limited="true" damping="1"/>
                  <geom name="L_joint10_marker" type="capsule" pos="0.01 0 0" size="0.004 0.01" euler="90 90 0" rgba="0 0 0 0" contype="0" conaffinity="0"/>
                  <geom type="mesh" mesh="Pointer2" contype="0" conaffinity="0" pos="-0.347 0.1815 0.055" euler="0 0 0"/>

                  <body name="L_link11" pos="0.027 0 0" gravcomp="1">
                    <joint name="L_joint11" type="hinge" pos="0 0 0" axis="0 1 0" range="0 20" limited="true" damping="1"/>
                    <geom name="L_joint11_marker" type="capsule" pos="0.01 0 0" size="0.004 0.01" euler="90 90 0" rgba="0 0 0 0" contype="0" conaffinity="0"/>
                    <geom type="mesh" mesh="Pointer3" contype="0" conaffinity="0" pos="-0.383 0.0685 0.117" euler="0 0 0"/>
                  </body>
                </body>
              </body>

              <body name="L_link12" pos="0.074 -0.012 -0.005" gravcomp="1" euler="0 0 -15">
                <joint name="L_joint12" type="hinge" pos="0 0 0" axis="0 1 0" range="0 20" limited="true" damping="1"/>
                <geom name="L_joint12_marker" type="capsule" pos="0.01 0 0" size="0.004 0.01" euler="90 90 0" rgba="0 0 0 0" contype="0" conaffinity="0"/>
                <geom type="mesh" mesh="Pointer1" contype="0" conaffinity="0" pos="-0.319 0.182 0.055" euler="0 0 0"/>

                <body name="L_link13" pos="0.027 0 0" gravcomp="1">
                  <joint name="L_joint13" type="hinge" pos="0 0 0" axis="0 1 0" range="0 20" limited="true" damping="1"/>
                  <geom name="L_joint13_marker" type="capsule" pos="0.01 0 0" size="0.004 0.01" euler="90 90 0" rgba="0 0 0 0" contype="0" conaffinity="0"/>
                  <geom type="mesh" mesh="Pointer2" contype="0" conaffinity="0" pos="-0.347 0.1815 0.055" euler="0 0 0"/>

                  <body name="L_link14" pos="0.027 0 0" gravcomp="1">
                    <joint name="L_joint14" type="hinge" pos="0 0 0" axis="0 1 0" range="0 20" limited="true" damping="1"/>
                    <geom name="L_joint14_marker" type="capsule" pos="0.01 0 0" size="0.004 0.01" euler="90 90 0" rgba="0 0 0 0" contype="0" conaffinity="0"/>
                    <geom type="mesh" mesh="Pointer3" contype="0" conaffinity="0" pos="-0.383 0.0685 0.117" euler="0 0 0"/>
                  </body>
                </body>
              </body>

              <body name="L_link15" pos="0.067 -0.033 -0.005" gravcomp="1" euler="0 0 -25">
                <joint name="L_joint15" type="hinge" pos="0 0 0" axis="0 1 0" range="0 20" limited="true" damping="1"/>
                <geom name="L_joint15_marker" type="capsule" pos="0.01 0 0" size="0.004 0.01" euler="90 90 0" rgba="0 0 0 0" contype="0" conaffinity="0"/>
                <geom type="mesh" mesh="Pointer1" contype="0" conaffinity="0" pos="-0.319 0.182 0.055" euler="0 0 0"/>

                <body name="L_link16" pos="0.027 0 0" gravcomp="1">
                  <joint name="L_joint16" type="hinge" pos="0 0 0" axis="0 1 0" range="0 20" limited="true" damping="1"/>
                  <geom name="L_joint16_marker" type="capsule" pos="0.01 0 0" size="0.004 0.01" euler="90 90 0" rgba="0 0 0 0" contype="0" conaffinity="0"/>
                  <geom type="mesh" mesh="Pointer2" contype="0" conaffinity="0" pos="-0.347 0.1815 0.055" euler="0 0 0"/>

                  <body name="L_link17" pos="0.027 0 0" gravcomp="1">
                    <joint name="L_joint17" type="hinge" pos="0 0 0" axis="0 1 0" range="0 20" limited="true" damping="1"/>
                    <geom name="L_joint17_marker" type="capsule" pos="0.01 0 0" size="0.004 0.01" euler="90 90 0" rgba="0 0 0 0" contype="0" conaffinity="0"/>
                    <geom type="mesh" mesh="Pointer3" contype="0" conaffinity="0" pos="-0.383 0.0685 0.117" euler="0 0 0"/>
                  </body>
                </body>
              </body>

            </body>
          </body>
        </body>
      </body>
    </body>

    <!-- RIGHT ARM -->
    <body name="R_base" pos="0 -0.22 0">
      <geom type="mesh" mesh="Shoulder" density="1000"/>

      <body name="R_link1" pos="-0.25 -0.1 -0.07">
        <joint name="R_joint1" type="hinge" pos="0 0 0" axis="0 0 1" range="-35 40" damping="1"/>
        <geom name="R_joint1_marker" type="sphere" pos="0 0 0" size="0.015" contype="0" conaffinity="0"/>
        <geom name="R_link1_vis" type="mesh" mesh="Bicep"
              contype="0" conaffinity="0"
              pos="0.24 0.145 0.07"
              euler="0 0 10.305"/>

        <body name="R_link2" pos="0.23 0.0344 -0.038" gravcomp="1">
          <joint name="R_joint2" type="hinge" pos="0 0 0" axis="0 1 0" range="-90 40" damping="1"/>
          <geom name="R_joint2_marker" type="sphere" pos="0 0 0" size="0.015" rgba="0 0 0 0" contype="0" conaffinity="0"/>
          <geom name="R_link2_vis" type="mesh" mesh="Elbow"
                contype="0" conaffinity="0"
                pos="0.03 0.11 0.11"
                euler="0 0 0"/>

          <body name="R_link3" pos="0 0 0" euler="0 0 11" gravcomp="1">
            <joint name="R_joint3" type="hinge" pos="0 0 0" axis="1 0 0" range="-90 180" damping="1" armature="0.01"/>
            <geom name="R_joint3_marker" type="sphere" pos="0 0 0" size="0.012" contype="0" conaffinity="0"/>
            <geom type="mesh" mesh="Forearm" contype="0" conaffinity="0"
                  pos="0.03 0.1 0.11"
                  euler="0 0 0"/>

            <body name="R_link4" pos="0.28 0 0" gravcomp="1">
              <geom name="R_joint4_marker" type="sphere" pos="0 0 0" size="0.015" rgba="0 0 0 0" contype="0" conaffinity="0"/>
              <geom name="R_link4_vis" type="mesh" mesh="Palm"
                    contype="0" conaffinity="0"
                    pos="-0.242 0.214 0.049"
                    euler="0 0 0"/>

              <body name="R_link5" pos="0 0.007 -0.005" gravcomp="1">
                <joint name="R_joint5" type="hinge" pos="0 0 0" axis="1 0 0" range="-35 40" damping="1"/>
                <geom name="R_joint5_marker" type="capsule" pos="0 0.025 0" size="0.004 0.02" euler="90 0 0" rgba="0 1 0 1" contype="0" conaffinity="0"/>
                <geom type="mesh" mesh="Palm2" contype="0" conaffinity="0" pos="-0.242 0.207 0.055" euler="0 0 0"/>

                <body name="R_flink9" pos="0 0.035 0" gravcomp="1" euler="90 0 0">
                  <joint name="R_fjoint9" type="hinge" pos="0 0 0" axis="0 1 0" range="0 40" limited="true" damping="1"/>
                  <geom name="R_fjoint9_marker" type="capsule" pos="0.01 0.0 -0.02" size="0.004 0.01" euler="0 0 0" rgba="0 1 0 1" contype="0" conaffinity="0"/>
                  <geom type="mesh" mesh="Thumb1" contype="0" conaffinity="0" pos="-0.255 0.12 -0.059" euler="-90 0 0"/>

                  <body name="R_flink10" pos="0.027 0 0" gravcomp="1">
                    <joint name="R_fjoint10" type="hinge" pos="0 0 0" axis="0 1 0" range="0 20" limited="true" damping="1"/>
                    <geom name="R_fjoint10_marker" type="capsule" pos="0.01 0 0" size="0.004 0.01" euler="0 0 0" rgba="0 0 0 0" contype="0" conaffinity="0"/>
                    <geom type="mesh" mesh="Thumb2" contype="0" conaffinity="0" pos="-0.283 0.12 -0.058" euler="-90 0 0"/>
                  </body>
                </body>
              </body>

              <body name="R_link6" pos="0.075 0.03 -0.007" gravcomp="1" euler="0 0 0">
                <joint name="R_joint6" type="hinge" pos="0 0 0" axis="0 1 0" range="0 20" limited="true" damping="1"/>
                <geom name="R_joint6_marker" type="capsule" pos="0.01 0 0" size="0.004 0.01" euler="90 90 0" rgba="0 1 0 1" contype="0" conaffinity="0"/>
                <geom type="mesh" mesh="Pointer1" contype="0" conaffinity="0" pos="-0.319 0.182 0.055" euler="0 0 0"/>

                <body name="R_link7" pos="0.027 0 0" gravcomp="1">
                  <joint name="R_joint7" type="hinge" pos="0 0 0" axis="0 1 0" range="0 20" limited="true" damping="1"/>
                  <geom name="R_joint7_marker" type="capsule" pos="0.01 0 0" size="0.004 0.01" euler="90 90 0" rgba="0 0 0 0" contype="0" conaffinity="0"/>
                  <geom type="mesh" mesh="Pointer2" contype="0" conaffinity="0" pos="-0.347 0.1815 0.055" euler="0 0 0"/>

                  <body name="R_link8" pos="0.027 0 0" gravcomp="1">
                    <joint name="R_joint8" type="hinge" pos="0 0 0" axis="0 1 0" range="0 20" limited="true" damping="1"/>
                    <geom name="R_joint8_marker" type="capsule" pos="0.01 0 0" size="0.004 0.01" euler="90 90 0" rgba="0 0 0 0" contype="0" conaffinity="0"/>
                    <geom type="mesh" mesh="Pointer3" contype="0" conaffinity="0" pos="-0.383 0.0685 0.117" euler="0 0 0"/>
                  </body>
                </body>
              </body>

              <body name="R_link9" pos="0.075 0.009 -0.006" gravcomp="1" euler="0 0 -10">
                <joint name="R_joint9" type="hinge" pos="0 0 0" axis="0 1 0" range="0 20" limited="true" damping="1"/>
                <geom name="R_joint9_marker" type="capsule" pos="0.01 0 0" size="0.004 0.01" euler="90 90 0" rgba="0 0 0 0" contype="0" conaffinity="0"/>
                <geom type="mesh" mesh="Pointer1" contype="0" conaffinity="0" pos="-0.319 0.182 0.055" euler="0 0 0"/>

                <body name="R_link10" pos="0.027 0 0" gravcomp="1">
                  <joint name="R_joint10" type="hinge" pos="0 0 0" axis="0 1 0" range="0 20" limited="true" damping="1"/>
                  <geom name="R_joint10_marker" type="capsule" pos="0.01 0 0" size="0.004 0.01" euler="90 90 0" rgba="0 0 0 0" contype="0" conaffinity="0"/>
                  <geom type="mesh" mesh="Pointer2" contype="0" conaffinity="0" pos="-0.347 0.1815 0.055" euler="0 0 0"/>

                  <body name="R_link11" pos="0.027 0 0" gravcomp="1">
                    <joint name="R_joint11" type="hinge" pos="0 0 0" axis="0 1 0" range="0 20" limited="true" damping="1"/>
                    <geom name="R_joint11_marker" type="capsule" pos="0.01 0 0" size="0.004 0.01" euler="90 90 0" rgba="0 0 0 0" contype="0" conaffinity="0"/>
                    <geom type="mesh" mesh="Pointer3" contype="0" conaffinity="0" pos="-0.383 0.0685 0.117" euler="0 0 0"/>
                  </body>
                </body>
              </body>

              <body name="R_link12" pos="0.074 -0.012 -0.005" gravcomp="1" euler="0 0 -15">
                <joint name="R_joint12" type="hinge" pos="0 0 0" axis="0 1 0" range="0 20" limited="true" damping="1"/>
                <geom name="R_joint12_marker" type="capsule" pos="0.01 0 0" size="0.004 0.01" euler="90 90 0" rgba="0 0 0 0" contype="0" conaffinity="0"/>
                <geom type="mesh" mesh="Pointer1" contype="0" conaffinity="0" pos="-0.319 0.182 0.055" euler="0 0 0"/>

                <body name="R_link13" pos="0.027 0 0" gravcomp="1">
                  <joint name="R_joint13" type="hinge" pos="0 0 0" axis="0 1 0" range="0 20" limited="true" damping="1"/>
                  <geom name="R_joint13_marker" type="capsule" pos="0.01 0 0" size="0.004 0.01" euler="90 90 0" rgba="0 0 0 0" contype="0" conaffinity="0"/>
                  <geom type="mesh" mesh="Pointer2" contype="0" conaffinity="0" pos="-0.347 0.1815 0.055" euler="0 0 0"/>

                  <body name="R_link14" pos="0.027 0 0" gravcomp="1">
                    <joint name="R_joint14" type="hinge" pos="0 0 0" axis="0 1 0" range="0 20" limited="true" damping="1"/>
                    <geom name="R_joint14_marker" type="capsule" pos="0.01 0 0" size="0.004 0.01" euler="90 90 0" rgba="0 0 0 0" contype="0" conaffinity="0"/>
                    <geom type="mesh" mesh="Pointer3" contype="0" conaffinity="0" pos="-0.383 0.0685 0.117" euler="0 0 0"/>
                  </body>
                </body>
              </body>

              <body name="R_link15" pos="0.067 -0.033 -0.005" gravcomp="1" euler="0 0 -25">
                <joint name="R_joint15" type="hinge" pos="0 0 0" axis="0 1 0" range="0 20" limited="true" damping="1"/>
                <geom name="R_joint15_marker" type="capsule" pos="0.01 0 0" size="0.004 0.01" euler="90 90 0" rgba="0 0 0 0" contype="0" conaffinity="0"/>
                <geom type="mesh" mesh="Pointer1" contype="0" conaffinity="0" pos="-0.319 0.182 0.055" euler="0 0 0"/>

                <body name="R_link16" pos="0.027 0 0" gravcomp="1">
                  <joint name="R_joint16" type="hinge" pos="0 0 0" axis="0 1 0" range="0 20" limited="true" damping="1"/>
                  <geom name="R_joint16_marker" type="capsule" pos="0.01 0 0" size="0.004 0.01" euler="90 90 0" rgba="0 0 0 0" contype="0" conaffinity="0"/>
                  <geom type="mesh" mesh="Pointer2" contype="0" conaffinity="0" pos="-0.347 0.1815 0.055" euler="0 0 0"/>

                  <body name="R_link17" pos="0.027 0 0" gravcomp="1">
                    <joint name="R_joint17" type="hinge" pos="0 0 0" axis="0 1 0" range="0 20" limited="true" damping="1"/>
                    <geom name="R_joint17_marker" type="capsule" pos="0.01 0 0" size="0.004 0.01" euler="90 90 0" rgba="0 0 0 0" contype="0" conaffinity="0"/>
                    <geom type="mesh" mesh="Pointer3" contype="0" conaffinity="0" pos="-0.383 0.0685 0.117" euler="0 0 0"/>
                  </body>
                </body>
              </body>

            </body>
          </body>
        </body>
      </body>
    </body>
  </worldbody>

  <tendon>
    <fixed name="L_finger1">
      <joint joint="L_joint6" coef="0.333333"/>
      <joint joint="L_joint7" coef="0.333333"/>
    </fixed>
    <fixed name="L_finger2">
      <joint joint="L_joint9" coef="0.333333"/>
      <joint joint="L_joint10" coef="0.333333"/>
    </fixed>
    <fixed name="L_finger3">
      <joint joint="L_joint12" coef="0.333333"/>
      <joint joint="L_joint13" coef="0.333333"/>
    </fixed>
    <fixed name="L_finger4">
      <joint joint="L_joint15" coef="0.333333"/>
      <joint joint="L_joint16" coef="0.333333"/>
    </fixed>
    <fixed name="L_thumb">
      <joint joint="L_fjoint9" coef="0.333333"/>
    </fixed>

    <fixed name="R_finger1">
      <joint joint="R_joint6" coef="0.333333"/>
      <joint joint="R_joint7" coef="0.333333"/>
    </fixed>
    <fixed name="R_finger2">
      <joint joint="R_joint9" coef="0.333333"/>
      <joint joint="R_joint10" coef="0.333333"/>
    </fixed>
    <fixed name="R_finger3">
      <joint joint="R_joint12" coef="0.333333"/>
      <joint joint="R_joint13" coef="0.333333"/>
    </fixed>
    <fixed name="R_finger4">
      <joint joint="R_joint15" coef="0.333333"/>
      <joint joint="R_joint16" coef="0.333333"/>
    </fixed>
    <fixed name="R_thumb">
      <joint joint="R_fjoint9" coef="0.333333"/>
    </fixed>
  </tendon>

  <equality>
    <joint name="L_j6_j7_couple" joint1="L_joint6" joint2="L_joint7" polycoef="0 1 0 0 0"/>
    <joint name="L_j7_j8_couple" joint1="L_joint7" joint2="L_joint8" polycoef="0 1 0 0 0"/>
    <joint name="L_j9_j10_couple" joint1="L_joint9" joint2="L_joint10" polycoef="0 1 0 0 0"/>
    <joint name="L_j10_j11_couple" joint1="L_joint10" joint2="L_joint11" polycoef="0 1 0 0 0"/>
    <joint name="L_j12_j13_couple" joint1="L_joint12" joint2="L_joint13" polycoef="0 1 0 0 0"/>
    <joint name="L_j13_j14_couple" joint1="L_joint13" joint2="L_joint14" polycoef="0 1 0 0 0"/>
    <joint name="L_j15_j16_couple" joint1="L_joint15" joint2="L_joint16" polycoef="0 1 0 0 0"/>
    <joint name="L_j16_j17_couple" joint1="L_joint16" joint2="L_joint17" polycoef="0 1 0 0 0"/>

    <joint name="R_j6_j7_couple" joint1="R_joint6" joint2="R_joint7" polycoef="0 1 0 0 0"/>
    <joint name="R_j7_j8_couple" joint1="R_joint7" joint2="R_joint8" polycoef="0 1 0 0 0"/>
    <joint name="R_j9_j10_couple" joint1="R_joint9" joint2="R_joint10" polycoef="0 1 0 0 0"/>
    <joint name="R_j10_j11_couple" joint1="R_joint10" joint2="R_joint11" polycoef="0 1 0 0 0"/>
    <joint name="R_j12_j13_couple" joint1="R_joint12" joint2="R_joint13" polycoef="0 1 0 0 0"/>
    <joint name="R_j13_j14_couple" joint1="R_joint13" joint2="R_joint14" polycoef="0 1 0 0 0"/>
    <joint name="R_j15_j16_couple" joint1="R_joint15" joint2="R_joint16" polycoef="0 1 0 0 0"/>
    <joint name="R_j16_j17_couple" joint1="R_joint16" joint2="R_joint17" polycoef="0 1 0 0 0"/>
  </equality>

  <actuator>
    <!-- LEFT ARM -->
    <motor name="L_Shoulder" joint="L_joint1" gear="1" ctrlrange="-10 10" ctrllimited="true" forcerange="-1.5 1.5" forcelimited="true"/>
    <motor name="L_Bicep" joint="L_joint2" gear="5"/>
    <motor name="L_Forearm" joint="L_joint3" gear="1"/>
    <motor name="L_Thumb_Joint" joint="L_joint5" gear="1" ctrlrange="-0.2 1.5" ctrllimited="true" forcerange="-1.5 1.5" forcelimited="true"/>
    <position name="L_Index" tendon="L_finger1" kp="5" ctrlrange="-1 0" ctrllimited="true" forcerange="-1.5 1.5" forcelimited="true"/>
    <position name="L_Middle" tendon="L_finger2" kp="5" ctrlrange="-1 0" ctrllimited="true" forcerange="-1.5 1.5" forcelimited="true"/>
    <position name="L_Ring" tendon="L_finger3" kp="5" ctrlrange="-1 0" ctrllimited="true" forcerange="-1.5 1.5" forcelimited="true"/>
    <position name="L_Pinky" tendon="L_finger4" kp="5" ctrlrange="-1 0" ctrllimited="true" forcerange="-1.5 1.5" forcelimited="true"/>
    <position name="L_Thumb" tendon="L_thumb" kp="5" ctrlrange="-0.3 0" ctrllimited="true" forcerange="-2.5 1.5" forcelimited="true"/>

    <!-- RIGHT ARM -->
    <motor name="R_Shoulder" joint="R_joint1" gear="1" ctrlrange="-10 10" ctrllimited="true" forcerange="-1.5 1.5" forcelimited="true"/>
    <motor name="R_Bicep" joint="R_joint2" gear="5"/>
    <motor name="R_Forearm" joint="R_joint3" gear="1"/>
    <motor name="R_Thumb_Joint" joint="R_joint5" gear="1" ctrlrange="-0.2 1.5" ctrllimited="true" forcerange="-1.5 1.5" forcelimited="true"/>
    <position name="R_Index" tendon="R_finger1" kp="5" ctrlrange="-1 0" ctrllimited="true" forcerange="-1.5 1.5" forcelimited="true"/>
    <position name="R_Middle" tendon="R_finger2" kp="5" ctrlrange="-1 0" ctrllimited="true" forcerange="-1.5 1.5" forcelimited="true"/>
    <position name="R_Ring" tendon="R_finger3" kp="5" ctrlrange="-1 0" ctrllimited="true" forcerange="-1.5 1.5" forcelimited="true"/>
    <position name="R_Pinky" tendon="R_finger4" kp="5" ctrlrange="-1 0" ctrllimited="true" forcerange="-1.5 1.5" forcelimited="true"/>
    <position name="R_Thumb" tendon="R_thumb" kp="5" ctrlrange="-0.3 0" ctrllimited="true" forcerange="-2.5 1.5" forcelimited="true"/>
  </actuator>
</mujoco>